[2024-07-08T00:11:39.548+0000] {taskinstance.py:1979} INFO - Dependencies all met for dep_context=non-requeueable deps ti=<TaskInstance: ml_workflow_SCASTRO.GetDataKaggle manual__2024-07-08T00:11:33.716194+00:00 [queued]>
[2024-07-08T00:11:39.563+0000] {taskinstance.py:1979} INFO - Dependencies all met for dep_context=requeueable deps ti=<TaskInstance: ml_workflow_SCASTRO.GetDataKaggle manual__2024-07-08T00:11:33.716194+00:00 [queued]>
[2024-07-08T00:11:39.563+0000] {taskinstance.py:2193} INFO - Starting attempt 1 of 2
[2024-07-08T00:11:39.589+0000] {taskinstance.py:2217} INFO - Executing <Task(PythonOperator): GetDataKaggle> on 2024-07-08 00:11:33.716194+00:00
[2024-07-08T00:11:39.598+0000] {standard_task_runner.py:60} INFO - Started process 111 to run task
[2024-07-08T00:11:39.603+0000] {standard_task_runner.py:87} INFO - Running: ['***', 'tasks', 'run', 'ml_workflow_SCASTRO', 'GetDataKaggle', 'manual__2024-07-08T00:11:33.716194+00:00', '--job-id', '33', '--raw', '--subdir', 'DAGS_FOLDER/dmc_pipeline.py', '--cfg-path', '/tmp/tmpvkclicxv']
[2024-07-08T00:11:39.605+0000] {standard_task_runner.py:88} INFO - Job 33: Subtask GetDataKaggle
[2024-07-08T00:11:39.676+0000] {task_command.py:423} INFO - Running <TaskInstance: ml_workflow_SCASTRO.GetDataKaggle manual__2024-07-08T00:11:33.716194+00:00 [running]> on host bf75f95c43a3
[2024-07-08T00:11:39.782+0000] {taskinstance.py:2513} INFO - Exporting env vars: AIRFLOW_CTX_DAG_OWNER='***' AIRFLOW_CTX_DAG_ID='ml_workflow_SCASTRO' AIRFLOW_CTX_TASK_ID='GetDataKaggle' AIRFLOW_CTX_EXECUTION_DATE='2024-07-08T00:11:33.716194+00:00' AIRFLOW_CTX_TRY_NUMBER='1' AIRFLOW_CTX_DAG_RUN_ID='manual__2024-07-08T00:11:33.716194+00:00'
[2024-07-08T00:11:39.791+0000] {taskinstance.py:2731} ERROR - Task failed with exception
Traceback (most recent call last):
  File "/home/airflow/.local/lib/python3.8/site-packages/airflow/models/taskinstance.py", line 444, in _execute_task
    result = _execute_callable(context=context, **execute_callable_kwargs)
  File "/home/airflow/.local/lib/python3.8/site-packages/airflow/models/taskinstance.py", line 414, in _execute_callable
    return execute_callable(context=context, **execute_callable_kwargs)
  File "/home/airflow/.local/lib/python3.8/site-packages/airflow/operators/python.py", line 200, in execute
    return_value = self.execute_callable()
  File "/home/airflow/.local/lib/python3.8/site-packages/airflow/operators/python.py", line 217, in execute_callable
    return self.python_callable(*self.op_args, **self.op_kwargs)
  File "/opt/airflow/dags/dmc_pipeline.py", line 36, in load_data
    df = pd.read_csv('train.csv',sep=",")
  File "/home/airflow/.local/lib/python3.8/site-packages/pandas/util/_decorators.py", line 211, in wrapper
    return func(*args, **kwargs)
  File "/home/airflow/.local/lib/python3.8/site-packages/pandas/util/_decorators.py", line 331, in wrapper
    return func(*args, **kwargs)
  File "/home/airflow/.local/lib/python3.8/site-packages/pandas/io/parsers/readers.py", line 950, in read_csv
    return _read(filepath_or_buffer, kwds)
  File "/home/airflow/.local/lib/python3.8/site-packages/pandas/io/parsers/readers.py", line 605, in _read
    parser = TextFileReader(filepath_or_buffer, **kwds)
  File "/home/airflow/.local/lib/python3.8/site-packages/pandas/io/parsers/readers.py", line 1442, in __init__
    self._engine = self._make_engine(f, self.engine)
  File "/home/airflow/.local/lib/python3.8/site-packages/pandas/io/parsers/readers.py", line 1735, in _make_engine
    self.handles = get_handle(
  File "/home/airflow/.local/lib/python3.8/site-packages/pandas/io/common.py", line 856, in get_handle
    handle = open(
FileNotFoundError: [Errno 2] No such file or directory: 'train.csv'
[2024-07-08T00:11:39.820+0000] {taskinstance.py:1149} INFO - Marking task as UP_FOR_RETRY. dag_id=ml_workflow_SCASTRO, task_id=GetDataKaggle, execution_date=20240708T001133, start_date=20240708T001139, end_date=20240708T001139
[2024-07-08T00:11:39.861+0000] {standard_task_runner.py:107} ERROR - Failed to execute job 33 for task GetDataKaggle ([Errno 2] No such file or directory: 'train.csv'; 111)
[2024-07-08T00:11:39.897+0000] {local_task_job_runner.py:234} INFO - Task exited with return code 1
[2024-07-08T00:11:39.982+0000] {taskinstance.py:3312} INFO - 0 downstream tasks scheduled from follow-on schedule check
