[2024-07-08T00:42:50.631+0000] {taskinstance.py:1979} INFO - Dependencies all met for dep_context=non-requeueable deps ti=<TaskInstance: ml_workflow_SCASTRO.GetDataKaggle manual__2024-07-08T00:37:41.971340+00:00 [queued]>
[2024-07-08T00:42:50.642+0000] {taskinstance.py:1979} INFO - Dependencies all met for dep_context=requeueable deps ti=<TaskInstance: ml_workflow_SCASTRO.GetDataKaggle manual__2024-07-08T00:37:41.971340+00:00 [queued]>
[2024-07-08T00:42:50.643+0000] {taskinstance.py:2193} INFO - Starting attempt 2 of 2
[2024-07-08T00:42:50.663+0000] {taskinstance.py:2217} INFO - Executing <Task(PythonOperator): GetDataKaggle> on 2024-07-08 00:37:41.971340+00:00
[2024-07-08T00:42:50.672+0000] {standard_task_runner.py:60} INFO - Started process 257 to run task
[2024-07-08T00:42:50.677+0000] {standard_task_runner.py:87} INFO - Running: ['***', 'tasks', 'run', 'ml_workflow_SCASTRO', 'GetDataKaggle', 'manual__2024-07-08T00:37:41.971340+00:00', '--job-id', '38', '--raw', '--subdir', 'DAGS_FOLDER/dmc_pipeline.py', '--cfg-path', '/tmp/tmpocnejjql']
[2024-07-08T00:42:50.679+0000] {standard_task_runner.py:88} INFO - Job 38: Subtask GetDataKaggle
[2024-07-08T00:42:50.747+0000] {task_command.py:423} INFO - Running <TaskInstance: ml_workflow_SCASTRO.GetDataKaggle manual__2024-07-08T00:37:41.971340+00:00 [running]> on host 0b9a6bf9906a
[2024-07-08T00:42:50.856+0000] {taskinstance.py:2513} INFO - Exporting env vars: AIRFLOW_CTX_DAG_OWNER='***' AIRFLOW_CTX_DAG_ID='ml_workflow_SCASTRO' AIRFLOW_CTX_TASK_ID='GetDataKaggle' AIRFLOW_CTX_EXECUTION_DATE='2024-07-08T00:37:41.971340+00:00' AIRFLOW_CTX_TRY_NUMBER='2' AIRFLOW_CTX_DAG_RUN_ID='manual__2024-07-08T00:37:41.971340+00:00'
[2024-07-08T00:42:50.865+0000] {taskinstance.py:2731} ERROR - Task failed with exception
Traceback (most recent call last):
  File "/home/airflow/.local/lib/python3.8/site-packages/airflow/models/taskinstance.py", line 444, in _execute_task
    result = _execute_callable(context=context, **execute_callable_kwargs)
  File "/home/airflow/.local/lib/python3.8/site-packages/airflow/models/taskinstance.py", line 414, in _execute_callable
    return execute_callable(context=context, **execute_callable_kwargs)
  File "/home/airflow/.local/lib/python3.8/site-packages/airflow/operators/python.py", line 200, in execute
    return_value = self.execute_callable()
  File "/home/airflow/.local/lib/python3.8/site-packages/airflow/operators/python.py", line 217, in execute_callable
    return self.python_callable(*self.op_args, **self.op_kwargs)
  File "/opt/airflow/dags/dmc_pipeline.py", line 36, in load_data
    df = pd.read_csv('train.csv',sep=",")
  File "/home/airflow/.local/lib/python3.8/site-packages/pandas/util/_decorators.py", line 211, in wrapper
    return func(*args, **kwargs)
  File "/home/airflow/.local/lib/python3.8/site-packages/pandas/util/_decorators.py", line 331, in wrapper
    return func(*args, **kwargs)
  File "/home/airflow/.local/lib/python3.8/site-packages/pandas/io/parsers/readers.py", line 950, in read_csv
    return _read(filepath_or_buffer, kwds)
  File "/home/airflow/.local/lib/python3.8/site-packages/pandas/io/parsers/readers.py", line 605, in _read
    parser = TextFileReader(filepath_or_buffer, **kwds)
  File "/home/airflow/.local/lib/python3.8/site-packages/pandas/io/parsers/readers.py", line 1442, in __init__
    self._engine = self._make_engine(f, self.engine)
  File "/home/airflow/.local/lib/python3.8/site-packages/pandas/io/parsers/readers.py", line 1735, in _make_engine
    self.handles = get_handle(
  File "/home/airflow/.local/lib/python3.8/site-packages/pandas/io/common.py", line 856, in get_handle
    handle = open(
FileNotFoundError: [Errno 2] No such file or directory: 'train.csv'
[2024-07-08T00:42:50.887+0000] {taskinstance.py:1149} INFO - Marking task as FAILED. dag_id=ml_workflow_SCASTRO, task_id=GetDataKaggle, execution_date=20240708T003741, start_date=20240708T004250, end_date=20240708T004250
[2024-07-08T00:42:50.904+0000] {standard_task_runner.py:107} ERROR - Failed to execute job 38 for task GetDataKaggle ([Errno 2] No such file or directory: 'train.csv'; 257)
[2024-07-08T00:42:50.929+0000] {local_task_job_runner.py:234} INFO - Task exited with return code 1
[2024-07-08T00:42:50.967+0000] {taskinstance.py:3312} INFO - 0 downstream tasks scheduled from follow-on schedule check
